Workbook

Sheet Parametri
A1: Parametru | B1: Valoare | C1: EIP item | D1: Durata luni | E1: =TODAY() -> 46161
A2: Schimb ulei interval (km) | B2: 10000 | C2: Scurtă | D2: 36
A3: Schimb ulei interval (zile) | B3: 180 | C3: Încălțăminte | D3: 18
A4: Schimb filtru aer (km) | B4: 20000 | C4: Costum | D4: 12
A5: Schimb filtru comb (km) | B5: 30000 | C5: Pantaloni | D5: 36
A6: Schimb bujii (km) | B6: 40000 | C6: Vestă avertizare | D6: 60
A7: Schimb lichid frana (luni) | B7: 24
A8: Schimb lichid racire (luni) | B8: 36
A9: Schimb curea distributie min (km) | B9: 80000
A10: Schimb curea distributie max (km) | B10: 120000
A11: Prag km alertă (km) | B11: 500
A12: Prag zile alertă (zile) | B12: 15

Sheet Șoferi
A1: Nume Prenume | B1: Nr. de pontaj | C1: Funcție | D1: Telefon | E1: Vehicul litere | F1: Vehicul cifre | G1: Sector | H1: Mărime haină | I1: Mărime încalțăminte | J1: Scurtă | K1: Încălțăminte | L1: Costum | M1: Pantaloni | N1: Vestă avertizare | O1: Urm. Scurtă | P1: Urm. Încălțăminte | Q1: Urm. Costum | R1: Urm. Pantaloni | S1: Urm. Vestă avertizare | T1: EIP complet? | U1: Observații
A2: Ababii Igor | B2: 6832 | C2: mașinist la excavatoare | D2: 061094258 | E2: TAE | F2: 470 | G2: CIOCANA | H2: 52-53 | I2: 45 | J2: 46082 | K2: 45323 | L2: 45717 | M2: 44986 | O2: =EDATE(J2,Parametri!$D$2) -> 47178 | P2: =EDATE(K2,Parametri!$D$3) -> 45870 | Q2: =EDATE(L2,Parametri!$D$4) -> 46082 | R2: =EDATE(M2,Parametri!$D$5) -> 46082 | S2: =EDATE(N2,Parametri!$D$6) -> 1827 | T2: =IF(COUNTIF(O2:S2,"nu")>0,"Incomplet","Complet") -> Complet
A3: Aftimiciuc Piotr | B3: 9072 | C3: maistru reparare | D3: 069108643 | E3: XXX | F3: 999 | G3: OFICIU | H3: 54 | I3: 46 | J3: 45231 | K3: 45597 | L3: 45352 | M3: NU E NEVOE | N3: 44013 | O3: =EDATE(J3,Parametri!$D$2) -> 46327 | P3: =EDATE(K3,Parametri!$D$3) -> 46143 | Q3: =EDATE(L3,Parametri!$D$4) -> 45717 | R3: =EDATE(M3,Parametri!$D$5) -> #VALUE! | S3: =EDATE(N3,Parametri!$D$6) -> 45839 | T3: =IF(COUNTIF(O3:S3,"nu")>0,"Incomplet","Complet") -> Complet
A4: Alexei Constantin | B4: 4394 | C4: mașinist la automacara | D4: 069079310 | E4: CGC | F4: 23 | G4: BAZA | H4: 54 | I4: 45 | J4: 46054 | K4: 45870 | L4: 45717 | M4: 44986 | N4: 45689 | O4: =EDATE(J4,Parametri!$D$2) -> 47150 | P4: =EDATE(K4,Parametri!$D$3) -> 46419 | Q4: =EDATE(L4,Parametri!$D$4) -> 46082 | R4: =EDATE(M4,Parametri!$D$5) -> 46082 | S4: =EDATE(N4,Parametri!$D$6) -> 47515 | T4: =IF(COUNTIF(O4:S4,"nu")>0,"Incomplet","Complet") -> Complet
A5: Alexei Constantin | B5: 4394 | C5: mașinist la automacara | D5: 069079310 | E5: CBE | F5: 638 | G5: BAZA | H5: 54 | I5: 45 | J5: =J4 -> 46054 | K5: =K4 -> 45870 | L5: =L4 -> 45717 | M5: =M4 -> 44986 | N5: =N4 -> 45689 | O5: =EDATE(J5,Parametri!$D$2) -> 47150 | P5: =EDATE(K5,Parametri!$D$3) -> 46419 | Q5: =EDATE(L5,Parametri!$D$4) -> 46082 | R5: =EDATE(M5,Parametri!$D$5) -> 46082 | S5: =EDATE(N5,Parametri!$D$6) -> 47515 | T5: =IF(COUNTIF(O5:S5,"nu")>0,"Incomplet","Complet") -> Complet
A6: Anton Marcel | B6: 4901 | C6: mașinist la excavatoare | D6: 069294876 | E6: TAE | F6: 470 | G6: CIOCANA | H6: 66 | I6: 46 | J6: 46054 | K6: 45870 | L6: 45992 | M6: 44986 | O6: =EDATE(J6,Parametri!$D$2) -> 47150 | P6: =EDATE(K6,Parametri!$D$3) -> 46419 | Q6: =EDATE(L6,Parametri!$D$4) -> 46357 | R6: =EDATE(M6,Parametri!$D$5) -> 46082 | S6: =EDATE(N6,Parametri!$D$6) -> 1827 | T6: =IF(COUNTIF(O6:S6,"nu")>0,"Incomplet","Complet") -> Complet
A7: Apavaloae Artur | B7: 8618 | C7: tractorist | D7: 069219281 | E7: CA | F7: 441 | G7: SBO | H7: 58-60 | I7: 45 | J7: 46082 | K7: 46023 | L7: 45778 | M7: 44986 | N7: 45689 | O7: =EDATE(J7,Parametri!$D$2) -> 47178 | P7: =EDATE(K7,Parametri!$D$3) -> 46569 | Q7: =EDATE(L7,Parametri!$D$4) -> 46143 | R7: =EDATE(M7,Parametri!$D$5) -> 46082 | S7: =EDATE(N7,Parametri!$D$6) -> 47515 | T7: =IF(COUNTIF(O7:S7,"nu")>0,"Incomplet","Complet") -> Complet
A8: Apavaloae Gheorghe | B8: 8981 | C8: conducator auto | D8: 069386933 | E8: CBE | F8: 276 | G8: BAZA | J8: 45778 | K8: 45323 | L8: 45717 | M8: NU E NEVOE | N8: 45689 | O8: =EDATE(J8,Parametri!$D$2) -> 46874 | P8: =EDATE(K8,Parametri!$D$3) -> 45870 | Q8: =EDATE(L8,Parametri!$D$4) -> 46082 | R8: =EDATE(M8,Parametri!$D$5) -> #VALUE! | S8: =EDATE(N8,Parametri!$D$6) -> 47515 | T8: =IF(COUNTIF(O8:S8,"nu")>0,"Incomplet","Complet") -> Complet
A9: Barbacari Gheorghi | B9: 9743 | C9: conducator auto | D9: 060122219 | E9: CBE | F9: 276 | G9: BAZA | H9: 66 | I9: 44 | J9: 46054 | K9: 46054 | L9: 46054 | M9: NU E NEVOE | N9: 46054 | O9: =EDATE(J9,Parametri!$D$2) -> 47150 | P9: =EDATE(K9,Parametri!$D$3) -> 46600 | Q9: =EDATE(L9,Parametri!$D$4) -> 46419 | R9: =EDATE(M9,Parametri!$D$5) -> #VALUE! | S9: =EDATE(N9,Parametri!$D$6) -> 47880 | T9: =IF(COUNTIF(O9:S9,"nu")>0,"Incomplet","Complet") -> Complet
A10: Boicu Iurie | B10: 7518 | C10: conducator auto | D10: 060587028 | E10: CCR | F10: 871 | G10: BAZA | H10: 52-53 | I10: 43 | J10: 46054 | K10: 45870 | L10: 45717 | M10: 44986 | N10: 45689 | O10: =EDATE(J10,Parametri!$D$2) -> 47150 | P10: =EDATE(K10,Parametri!$D$3) -> 46419 | Q10: =EDATE(L10,Parametri!$D$4) -> 46082 | R10: =EDATE(M10,Parametri!$D$5) -> 46082 | S10: =EDATE(N10,Parametri!$D$6) -> 47515 | T10: =IF(COUNTIF(O10:S10,"nu")>0,"Incomplet","Complet") -> Complet
A11: Caimacan Ruslan | B11: 7886 | C11: tractorist | D11: 069524215 | E11: TAW | F11: 114 | G11: VADUL LUI VODA | H11: 54 | I11: 45 | J11: 45658 | K11: 45901 | L11: 45717 | M11: 45901 | N11: 45689 | O11: =EDATE(J11,Parametri!$D$2) -> 46753 | P11: =EDATE(K11,Parametri!$D$3) -> 46447 | Q11: =EDATE(L11,Parametri!$D$4) -> 46082 | R11: =EDATE(M11,Parametri!$D$5) -> 46997 | S11: =EDATE(N11,Parametri!$D$6) -> 47515 | T11: =IF(COUNTIF(O11:S11,"nu")>0,"Incomplet","Complet") -> Complet
A12: Caimacan Ruslan | B12: 7886 | C12: tractorist | D12: 069524215 | E12: CC | F12: 322 | G12: VADUL LUI VODA | H12: 54 | I12: 45 | J12: =J11 -> 45658 | K12: =K11 -> 45901 | L12: =L11 -> 45717 | M12: =M11 -> 45901 | N12: =N11 -> 45689 | O12: =EDATE(J12,Parametri!$D$2) -> 46753 | P12: =EDATE(K12,Parametri!$D$3) -> 46447 | Q12: =EDATE(L12,Parametri!$D$4) -> 46082 | R12: =EDATE(M12,Parametri!$D$5) -> 46997 | S12: =EDATE(N12,Parametri!$D$6) -> 47515 | T12: =IF(COUNTIF(O12:S12,"nu")>0,"Incomplet","Complet") -> Complet
A13: Caradja Iurii | B13: 7949 | C13: lăcătuș | D13: 079744836 | E13: XXX | F13: 999 | G13: GARAJ | H13: 50-52 | I13: 43 | J13: 45658 | K13: 45717 | L13: 45566 | M13: 44562 | N13: NU E NEVOE | O13: =EDATE(J13,Parametri!$D$2) -> 46753 | P13: =EDATE(K13,Parametri!$D$3) -> 46266 | Q13: =EDATE(L13,Parametri!$D$4) -> 45931 | R13: =EDATE(M13,Parametri!$D$5) -> 45658 | S13: =EDATE(N13,Parametri!$D$6) -> #VALUE! | T13: =IF(COUNTIF(O13:S13,"nu")>0,"Incomplet","Complet") -> Complet
A14: Castraveț Constantin | B14: 8772 | C14: mașinist la buldozer | D14: 069608568 | E14: CC | F14: 325 | G14: SBO | H14: 50-52 | I14: 43 | J14: 45658 | K14: 45870 | L14: 45717 | M14: 44562 | N14: 45689 | O14: =EDATE(J14,Parametri!$D$2) -> 46753 | P14: =EDATE(K14,Parametri!$D$3) -> 46419 | Q14: =EDATE(L14,Parametri!$D$4) -> 46082 | R14: =EDATE(M14,Parametri!$D$5) -> 45658 | S14: =EDATE(N14,Parametri!$D$6) -> 47515 | T14: =IF(COUNTIF(O14:S14,"nu")>0,"Incomplet","Complet") -> Complet
A15: Cauș Timofei | B15: 538 | C15: mașinist la automacara | D15: 069756270 | E15: CFK | F15: 906 | G15: BAZA | H15: 54 | I15: 42 | J15: 45566 | K15: 45870 | L15: 45717 | M15: NU E NEVOE | N15: 45931 | O15: =EDATE(J15,Parametri!$D$2) -> 46661 | P15: =EDATE(K15,Parametri!$D$3) -> 46419 | Q15: =EDATE(L15,Parametri!$D$4) -> 46082 | R15: =EDATE(M15,Parametri!$D$5) -> #VALUE! | S15: =EDATE(N15,Parametri!$D$6) -> 47757 | T15: =IF(COUNTIF(O15:S15,"nu")>0,"Incomplet","Complet") -> Complet
A16: Cebanu Vitalie | B16: 8994 | C16: mașinist la excavatoare | D16: 060038651 | E16: TAE | F16: 586 | G16: BAZA | H16: 50-53 | I16: 43 | J16: 46054 | K16: 45323 | L16: 45717 | M16: 44986 | N16: 45689 | O16: =EDATE(J16,Parametri!$D$2) -> 47150 | P16: =EDATE(K16,Parametri!$D$3) -> 45870 | Q16: =EDATE(L16,Parametri!$D$4) -> 46082 | R16: =EDATE(M16,Parametri!$D$5) -> 46082 | S16: =EDATE(N16,Parametri!$D$6) -> 47515 | T16: =IF(COUNTIF(O16:S16,"nu")>0,"Incomplet","Complet") -> Complet
A17: Cebotari Constantin | B17: 9633 | C17: tractorist | D17: 068437671 | E17: CH | F17: 340 | G17: BAZA | J17: 45931 | K17: 45717 | L17: 45717 | N17: 45717 | O17: =EDATE(J17,Parametri!$D$2) -> 47027 | P17: =EDATE(K17,Parametri!$D$3) -> 46266 | Q17: =EDATE(L17,Parametri!$D$4) -> 46082 | R17: =EDATE(M17,Parametri!$D$5) -> 1096 | S17: =EDATE(N17,Parametri!$D$6) -> 47543 | T17: =IF(COUNTIF(O17:S17,"nu")>0,"Incomplet","Complet") -> Complet
A18: Celpan Ion | B18: 4984 | C18: mașinist la excavatoare | D18: 069501965 | E18: CA | F18: 76 | G18: BAZA | H18: 52 | I18: 42 | J18: 01.04.2025 | K18: 45717 | L18: 45717 | M18: 44621 | N18: 45689 | O18: =EDATE(J18,Parametri!$D$2) -> 46844 | P18: =EDATE(K18,Parametri!$D$3) -> 46266 | Q18: =EDATE(L18,Parametri!$D$4) -> 46082 | R18: =EDATE(M18,Parametri!$D$5) -> 45717 | S18: =EDATE(N18,Parametri!$D$6) -> 47515 | T18: =IF(COUNTIF(O18:S18,"nu")>0,"Incomplet","Complet") -> Complet
A19: Cernei Anatolii | B19: 2641 | C19: conducator auto | D19: 069112876 | E19: SYR | F19: 769 | G19: BAZA | H19: 44-46 | I19: 42 | J19: 45566 | K19: 45870 | L19: 45717 | M19: NU E NEVOE | N19: 45689 | O19: =EDATE(J19,Parametri!$D$2) -> 46661 | P19: =EDATE(K19,Parametri!$D$3) -> 46419 | Q19: =EDATE(L19,Parametri!$D$4) -> 46082 | R19: =EDATE(M19,Parametri!$D$5) -> #VALUE! | S19: =EDATE(N19,Parametri!$D$6) -> 47515 | T19: =IF(COUNTIF(O19:S19,"nu")>0,"Incomplet","Complet") -> Complet
A20: Cheptene Serghei | B20: 545 | C20: mașinist la excavatoare | D20: 069584366 | E20: TAE | F20: 472 | G20: CENTRU | H20: 52 | I20: 43 | J20: 45658 | K20: 45870 | L20: 45505 | M20: 44562 | N20: 45931 | O20: =EDATE(J20,Parametri!$D$2) -> 46753 | P20: =EDATE(K20,Parametri!$D$3) -> 46419 | Q20: =EDATE(L20,Parametri!$D$4) -> 45870 | R20: =EDATE(M20,Parametri!$D$5) -> 45658 | S20: =EDATE(N20,Parametri!$D$6) -> 47757 | T20: =IF(COUNTIF(O20:S20,"nu")>0,"Incomplet","Complet") -> Complet
A21: Cotai Liviu | B21: 6463 | C21: mașinist la excavatoare | D21: 068478615 | E21: MRZ | F21: 370 | G21: CENTRU | H21: 52-53 | I21: 42 | J21: 45658 | K21: 45870 | L21: 45931 | M21: 44562 | O21: =EDATE(J21,Parametri!$D$2) -> 46753 | P21: =EDATE(K21,Parametri!$D$3) -> 46419 | Q21: =EDATE(L21,Parametri!$D$4) -> 46296 | R21: =EDATE(M21,Parametri!$D$5) -> 45658 | S21: =EDATE(N21,Parametri!$D$6) -> 1827 | T21: =IF(COUNTIF(O21:S21,"nu")>0,"Incomplet","Complet") -> Complet
A22: Cotai Liviu | B22: 6463 | C22: mașinist la excavatoare | D22: 068478615 | E22: TAE | F22: 465 | G22: CENTRU | H22: 52-53 | I22: 42 | J22: =J21 -> 45658 | K22: =K21 -> 45870 | L22: =L21 -> 45931 | M22: =M21 -> 44562 | N22: =N21 -> 0 | O22: =EDATE(J22,Parametri!$D$2) -> 46753 | P22: =EDATE(K22,Parametri!$D$3) -> 46419 | Q22: =EDATE(L22,Parametri!$D$4) -> 46296 | R22: =EDATE(M22,Parametri!$D$5) -> 45658 | S22: =EDATE(N22,Parametri!$D$6) -> 1827 | T22: =IF(COUNTIF(O22:S22,"nu")>0,"Incomplet","Complet") -> Complet
A23: Cotai Liviu | B23: 6463 | C23: mașinist la excavatoare | D23: 068478615 | E23: SYR | F23: 780 | G23: CENTRU | H23: 52-53 | I23: 42 | J23: =J22 -> 45658 | K23: =K22 -> 45870 | L23: =L22 -> 45931 | M23: =M22 -> 44562 | N23: =N22 -> 0 | O23: =EDATE(J23,Parametri!$D$2) -> 46753 | P23: =EDATE(K23,Parametri!$D$3) -> 46419 | Q23: =EDATE(L23,Parametri!$D$4) -> 46296 | R23: =EDATE(M23,Parametri!$D$5) -> 45658 | S23: =EDATE(N23,Parametri!$D$6) -> 1827 | T23: =IF(COUNTIF(O23:S23,"nu")>0,"Incomplet","Complet") -> Complet
A24: David Ivan | B24: 8988 | C24: conducator auto | D24: 060130100 | E24: CHN | F24: 349 | G24: BAZA | H24: 48-50 | I24: 41 | J24: 45658 | K24: 45870 | L24: 45931 | M24: 44562 | N24: 45689 | O24: =EDATE(J24,Parametri!$D$2) -> 46753 | P24: =EDATE(K24,Parametri!$D$3) -> 46419 | Q24: =EDATE(L24,Parametri!$D$4) -> 46296 | R24: =EDATE(M24,Parametri!$D$5) -> 45658 | S24: =EDATE(N24,Parametri!$D$6) -> 47515 | T24: =IF(COUNTIF(O24:S24,"nu")>0,"Incomplet","Complet") -> Complet
A25: Furnica Ion | B25: 1305 | C25: mașinist la excavatoare | D25: 069129092 | E25: MRZ | F25: 40 | G25: BUIUCANI | H25: 54 | I25: 43 | J25: 46054 | K25: 45870 | L25: 45931 | M25: 44986 | N25: 45717 | O25: =EDATE(J25,Parametri!$D$2) -> 47150 | P25: =EDATE(K25,Parametri!$D$3) -> 46419 | Q25: =EDATE(L25,Parametri!$D$4) -> 46296 | R25: =EDATE(M25,Parametri!$D$5) -> 46082 | S25: =EDATE(N25,Parametri!$D$6) -> 47543 | T25: =IF(COUNTIF(O25:S25,"nu")>0,"Incomplet","Complet") -> Complet
A26: Furnica Ion | B26: 1305 | C26: mașinist la excavatoare | D26: 069129092 | E26: TAE | F26: 466 | G26: BUIUCANI | H26: 54 | I26: 43 | J26: =J25 -> 46054 | K26: =K25 -> 45870 | L26: =L25 -> 45931 | M26: =M25 -> 44986 | N26: =N25 -> 45717 | O26: =EDATE(J26,Parametri!$D$2) -> 47150 | P26: =EDATE(K26,Parametri!$D$3) -> 46419 | Q26: =EDATE(L26,Parametri!$D$4) -> 46296 | R26: =EDATE(M26,Parametri!$D$5) -> 46082 | S26: =EDATE(N26,Parametri!$D$6) -> 47543 | T26: =IF(COUNTIF(O26:S26,"nu")>0,"Incomplet","Complet") -> Complet
A27: Furnica Ion | B27: 1305 | C27: mașinist la excavatoare | D27: 069129092 | E27: SYR | F27: 744 | G27: BUIUCANI | H27: 54 | I27: 43 | J27: =J26 -> 46054 | K27: =K26 -> 45870 | L27: =L26 -> 45931 | M27: =M26 -> 44986 | N27: =N26 -> 45717 | O27: =EDATE(J27,Parametri!$D$2) -> 47150 | P27: =EDATE(K27,Parametri!$D$3) -> 46419 | Q27: =EDATE(L27,Parametri!$D$4) -> 46296 | R27: =EDATE(M27,Parametri!$D$5) -> 46082 | S27: =EDATE(N27,Parametri!$D$6) -> 47543 | T27: =IF(COUNTIF(O27:S27,"nu")>0,"Incomplet","Complet") -> Complet
A28: Ghimpu Dan | B28: 9711 | C28: Inginer | D28: 069848101 | E28: XXX | F28: 999 | G28: OFICIU | H28: 50 | I28: 44 | J28: 45931 | K28: 45931 | L28: 46082 | M28: NU E NEVOE | N28: NU E NEVOE | O28: =EDATE(J28,Parametri!$D$2) -> 47027 | P28: =EDATE(K28,Parametri!$D$3) -> 46478 | Q28: =EDATE(L28,Parametri!$D$4) -> 46447 | R28: =EDATE(M28,Parametri!$D$5) -> #VALUE! | S28: =EDATE(N28,Parametri!$D$6) -> #VALUE! | T28: =IF(COUNTIF(O28:S28,"nu")>0,"Incomplet","Complet") -> Complet
A29: Gonciarenco Vieceslav | B29: 2360 | C29: mașinist la excavatoare | D29: 069567986 | E29: TAE | F29: 587 | G29: BAZA | H29: 54 | I29: 43 | J29: 45658 | K29: 45870 | L29: 45778 | M29: 45778 | N29: 45689 | O29: =EDATE(J29,Parametri!$D$2) -> 46753 | P29: =EDATE(K29,Parametri!$D$3) -> 46419 | Q29: =EDATE(L29,Parametri!$D$4) -> 46143 | R29: =EDATE(M29,Parametri!$D$5) -> 46874 | S29: =EDATE(N29,Parametri!$D$6) -> 47515 | T29: =IF(COUNTIF(O29:S29,"nu")>0,"Incomplet","Complet") -> Complet
A30: Goreanu Anatolie | B30: 8913 | C30: conducator auto | D30: 078922447 | E30: CBE | F30: 284 | G30: BAZA | H30: 48-50 | I30: 42 | J30: 45566 | K30: 46082 | L30: 45444 | M30: NU E NEVOE | N30: 44317 | O30: =EDATE(J30,Parametri!$D$2) -> 46661 | P30: =EDATE(K30,Parametri!$D$3) -> 46631 | Q30: =EDATE(L30,Parametri!$D$4) -> 45809 | R30: =EDATE(M30,Parametri!$D$5) -> #VALUE! | S30: =EDATE(N30,Parametri!$D$6) -> 46143 | T30: =IF(COUNTIF(O30:S30,"nu")>0,"Incomplet","Complet") -> Complet
A31: Grama Fiodor | B31: 9383 | C31: mașinist la excavatoare | D31: 060406794 | E31: MRZ | F31: 373 | G31: BRANSAMENTE | J31: 45566 | K31: 45748 | L31: 45931 | O31: =EDATE(J31,Parametri!$D$2) -> 46661 | P31: =EDATE(K31,Parametri!$D$3) -> 46296 | Q31: =EDATE(L31,Parametri!$D$4) -> 46296 | R31: =EDATE(M31,Parametri!$D$5) -> 1096 | S31: =EDATE(N31,Parametri!$D$6) -> 1827 | T31: =IF(COUNTIF(O31:S31,"nu")>0,"Incomplet","Complet") -> Complet
A32: Grama Fiodor | B32: 9383 | C32: mașinist la excavatoare | D32: 060406794 | E32: TAE | F32: 469 | G32: BRANSAMENTE | J32: =J31 -> 45566 | K32: =K31 -> 45748 | L32: =L31 -> 45931 | M32: =M31 -> 0 | N32: =N31 -> 0 | O32: =EDATE(J32,Parametri!$D$2) -> 46661 | P32: =EDATE(K32,Parametri!$D$3) -> 46296 | Q32: =EDATE(L32,Parametri!$D$4) -> 46296 | R32: =EDATE(M32,Parametri!$D$5) -> 1096 | S32: =EDATE(N32,Parametri!$D$6) -> 1827 | T32: =IF(COUNTIF(O32:S32,"nu")>0,"Incomplet","Complet") -> Complet
A33: Grama Fiodor | B33: 9383 | C33: mașinist la excavatoare | D33: 060406794 | E33: SYR | F33: 747 | G33: BRANSAMENTE | J33: =J32 -> 45566 | K33: =K32 -> 45748 | L33: =L32 -> 45931 | M33: =M32 -> 0 | N33: =N32 -> 0 | O33: =EDATE(J33,Parametri!$D$2) -> 46661 | P33: =EDATE(K33,Parametri!$D$3) -> 46296 | Q33: =EDATE(L33,Parametri!$D$4) -> 46296 | R33: =EDATE(M33,Parametri!$D$5) -> 1096 | S33: =EDATE(N33,Parametri!$D$6) -> 1827 | T33: =IF(COUNTIF(O33:S33,"nu")>0,"Incomplet","Complet") -> Complet
A34: Iacub Alexandru | B34: 9161 | C34: conducator auto | D34: 068405411 | E34: CBI | F34: 96 | G34: VADUL LUI VODA | H34: 54 | I34: 43 | J34: 46023 | K34: 45323 | L34: 45536 | M34: NU E NEVOE | N34: 45689 | O34: =EDATE(J34,Parametri!$D$2) -> 47119 | P34: =EDATE(K34,Parametri!$D$3) -> 45870 | Q34: =EDATE(L34,Parametri!$D$4) -> 45901 | R34: =EDATE(M34,Parametri!$D$5) -> #VALUE! | S34: =EDATE(N34,Parametri!$D$6) -> 47515 | T34: =IF(COUNTIF(O34:S34,"nu")>0,"Incomplet","Complet") -> Complet
A35: Iacub Alexandru | B35: 9161 | C35: conducator auto | D35: 068405411 | E35: CBE | F35: 648 | G35: VADUL LUI VODA | H35: 54 | I35: 43 | J35: =J34 -> 46023 | K35: =K34 -> 45323 | L35: =L34 -> 45536 | M35: =M34 -> NU E NEVOE | N35: =N34 -> 45689 | O35: =EDATE(J35,Parametri!$D$2) -> 47119 | P35: =EDATE(K35,Parametri!$D$3) -> 45870 | Q35: =EDATE(L35,Parametri!$D$4) -> 45901 | R35: =EDATE(M35,Parametri!$D$5) -> #VALUE! | S35: =EDATE(N35,Parametri!$D$6) -> 47515 | T35: =IF(COUNTIF(O35:S35,"nu")>0,"Incomplet","Complet") -> Complet
A36: Maistrovoi Alexandru | B36: 8980 | C36: mașinist la excavatoare | D36: 061024885 | E36: TAE | F36: 473 | G36: BOTANICA | H36: 52-54 | I36: 42 | J36: 45658 | K36: 45870 | L36: 45778 | M36: 45901 | N36: 45717 | O36: =EDATE(J36,Parametri!$D$2) -> 46753 | P36: =EDATE(K36,Parametri!$D$3) -> 46419 | Q36: =EDATE(L36,Parametri!$D$4) -> 46143 | R36: =EDATE(M36,Parametri!$D$5) -> 46997 | S36: =EDATE(N36,Parametri!$D$6) -> 47543 | T36: =IF(COUNTIF(O36:S36,"nu")>0,"Incomplet","Complet") -> Complet
A37: Manole Serghei | B37: 8617 | C37: tractorist | D37: 061018830 | E37: TBN | F37: 329 | G37: SBO | H37: 50-52 | I37: 42 | J37: 46054 | K37: 45931 | L37: 45931 | M37: 44986 | N37: 45931 | O37: =EDATE(J37,Parametri!$D$2) -> 47150 | P37: =EDATE(K37,Parametri!$D$3) -> 46478 | Q37: =EDATE(L37,Parametri!$D$4) -> 46296 | R37: =EDATE(M37,Parametri!$D$5) -> 46082 | S37: =EDATE(N37,Parametri!$D$6) -> 47757 | T37: =IF(COUNTIF(O37:S37,"nu")>0,"Incomplet","Complet") -> Complet
A38: Manole Serghei | B38: 8617 | C38: tractorist | D38: 061018830 | E38: RTL | F38: 362 | G38: SBO | H38: 50-52 | I38: 42 | J38: =J37 -> 46054 | K38: =K37 -> 45931 | L38: =L37 -> 45931 | M38: =M37 -> 44986 | N38: =N37 -> 45931 | O38: =EDATE(J38,Parametri!$D$2) -> 47150 | P38: =EDATE(K38,Parametri!$D$3) -> 46478 | Q38: =EDATE(L38,Parametri!$D$4) -> 46296 | R38: =EDATE(M38,Parametri!$D$5) -> 46082 | S38: =EDATE(N38,Parametri!$D$6) -> 47757 | T38: =IF(COUNTIF(O38:S38,"nu")>0,"Incomplet","Complet") -> Complet
A39: Mardari Ion | B39: 8898 | C39: lăcătuș | D39: 069019876 | E39: XXX | F39: 999 | G39: GARAJ | H39: 50 | I39: 41 | J39: 45566 | K39: 45717 | L39: 45809 | M39: 44896 | N39: NU E NEVOE | O39: =EDATE(J39,Parametri!$D$2) -> 46661 | P39: =EDATE(K39,Parametri!$D$3) -> 46266 | Q39: =EDATE(L39,Parametri!$D$4) -> 46174 | R39: =EDATE(M39,Parametri!$D$5) -> 45992 | S39: =EDATE(N39,Parametri!$D$6) -> #VALUE! | T39: =IF(COUNTIF(O39:S39,"nu")>0,"Incomplet","Complet") -> Complet
A40: Matei Fiodor | B40: 8222 | C40: tractorist | D40: 069214997 | E40: TBN | F40: 329 | G40: SBO | H40: 52-54 | I40: 43 | J40: 46054 | K40: 45627 | L40: 45717 | M40: 44986 | O40: =EDATE(J40,Parametri!$D$2) -> 47150 | P40: =EDATE(K40,Parametri!$D$3) -> 46174 | Q40: =EDATE(L40,Parametri!$D$4) -> 46082 | R40: =EDATE(M40,Parametri!$D$5) -> 46082 | S40: =EDATE(N40,Parametri!$D$6) -> 1827 | T40: =IF(COUNTIF(O40:S40,"nu")>0,"Incomplet","Complet") -> Complet
...

Sheet Vehicule
A1: Nr. Garaj | B1: Destinatia | C1: Marcă / Model | D1: Nr. înmatriculare | E1: Nr. înmatriculare | F1: Nr. înmatriculare | G1: Nr. Inventar | H1: An fabricație | I1: Km actuali | J1: p63, | K1: Șofer curent | L1: Utilaje auxiliare | M1: Lucrari necesate efectuat luna viitoare
A2: 1 | B2: Excavatoare | C2: JCB 3CX | D2: TAE | E2: 471 | F2: TAE 471 | G2: 42692096 | H2: 2016 | J2: Râșcani (1) | K2: Rotari Oleg / Triboi Vasilii
A3: 2 | B3: Excavatoare | C3: JCB 3CX | D3: TAE | E3: 472 | F3: TAE 472 | G3: 42691896 | H3: 2016 | J3: Centru (2) | K3: Cheptene Segei / Vieru Mihail
A4: 3 | B4: Excavatoare | C4: JCB 3CX | D4: TAE | E4: 474 | F4: TAE 474 | G4: 42692296 | H4: 2016 | J4: Buiucani (3) | K4: Olari Gheorghii / Sabanciuc Mihail
A5: 4 | B5: Excavatoare | C5: JCB 3CX | D5: TAE | E5: 473 | F5: TAE 473 | G5: 42691996 | H5: 2016 | J5: Botanica (4) | K5: Melnic Valentin / Maistrovoi Alexandru
A6: 6 | B6: Duldozer | C6: DZ 42 | D6: CC | E6: 325 | F6: CC 325 | G6: 42492400 | H6: 1996 | J6: SBO | K6: Castraveț Constantin
A7: 8 | B7: Tractor | C7: Foton 545 | D7: CH | E7: 340 | F7: CH 340 | G7: 41316100 | H7: 2011 | J7: SBO | K7: ???
A8: 9 | B8: Excavatoare | C8: JCB 3CX | D8: TAE | E8: 470 | F8: TAE 470 | G8: 42692196 | H8: 2016 | J8: Ciocana (5) | K8: Ababii Igor / Anton Marcel
A9: 10 | B9: Excavatoare | C9: JCB 3CX | D9: TAE | E9: 586 | F9: TAE 586 | G9: 42692496 | H9: 2016 | J9: Repartizare | K9: Muntean Niconor / Ceban Vitalie
A10: 11 | B10: Excavatoare | C10: JCB 3CX | D10: TAE | E10: 587 | F10: TAE 587 | G10: 42692396 | H10: 2016 | J10: Repartizare | K10: Goncearenco Veaceslav
A11: 13 | B11: Tractor | C11: T-150K | D11: CA | E11: 441 | F11: CA 441 | G11: 41246300 | H11: 1998 | J11: SBO | K11: Apavaloae Artur / Manole Seghei / Matei Fiodor / Mocanu Petru
A12: 15 | B12: Tractor | C12: XTZ 150 | D12: CA | E12: 530 | F12: CA 530 | G12: 41294600 | H12: 2005 | J12: SBO | K12: Soltan Victor / Zatic Vitalie
A13: 16 | B13: Bara | C13: XTZ 150 | D13: CA | E13: 317 | F13: CA 317 | G13: 41294700 | H13: 2005 | J13: Repartizare | K13: Timotin Grigorii / Prisacari Valeriu
A14: 17 | B14: Remorcă | C14: vechi | D14: CRT | E14: 144 | F14: CRT 144 | G14: 50059000 | J14: SBO | K14: Soltan Victor / Zatic Vitalie
A15: 19 | B15: Remorcă | C15: vechi | D15: CRT | E15: 142 | F15: CRT 142 | G15: 50058900 | J15: SBO | K15: Apavaloae Artur / Manole Seghei / Matei Fiodor / Mocanu Petru
A16: 21 | B16: Excavatoare | C16: JCB 8030 ZTS | D16: TAE | E16: 464 | F16: TAE 464 | G16: 42691296 | H16: 2016 | J16: Râșcani (1) | K16: Verbițchii Mihail
A17: 22 | B17: Excavatoare | C17: JCB 8030 ZTS | D17: TAE | E17: 465 | F17: TAE 465 | G17: 42691396 | H17: 2016 | J17: Centru (2) | K17: Cotai Liviu
A18: 23 | B18: Excavatoare | C18: JCB 8030 ZTS | D18: TAE | E18: 466 | F18: TAE 466 | G18: 42691496 | H18: 2016 | J18: Buiucani (3) | K18: Furnica Ion
A19: 24 | B19: Excavatoare | C19: JCB 8030 ZTS | D19: TAE | E19: 467 | F19: TAE 467 | G19: 42691596 | H19: 2016 | J19: Botanica (4) | K19: Pascaru Vasile
A20: 33 | B20: Excavatoare | C20: JCB 8030 ZTS | D20: TAE | E20: 468 | F20: TAE 468 | G20: 42691696 | H20: 2016 | J20: Ciocana (5) | K20: Sclifos Zaharia
A21: 34 | B21: Excavatoare | C21: JCB 8030 ZTS | D21: TAE | E21: 469 | F21: TAE 469 | G21: 42691796 | H21: 2016 | J21: Branșamente | K21: Grama Fiodor
A22: 37 | B22: Bara | C22: MTZ-82 | D22: CA | E22: 786 | F22: CA 786 | G22: 41248600 | H22: 1999 | J22: Repartizare | K22: Prisacari Valeriu
A23: 43 | B23: Pompă | C23: MTZ-82 | D23: CA | E23: 468 | F23: CA 468 | G23: 41246700 | H23: 1998 | J23: Repartizare | K23: Timotin Andrei
A24: 45 | B24: Bara | C24: MTZ-82 | D24: CA | E24: 531 | F24: CA 531 | G24: 41244200 | H24: 1998 | J24: Repartizare | K24: Timotin Grigorii
A25: 53 | B25: Excavatoare | C25: ĂO-2621 | D25: CA | E25: 76 | F25: CA 076 | G25: 42402400 | H25: 1994 | J25: Repartizare | K25: Celpan Ion
A26: 55 | B26: Încărcător | C26: DZ 133 | D26: CC | E26: 545 | F26: CC 545 | G26: 41286300 | H26: 2002 | J26: SBO | K26: Popa Constatin
A27: 67 | B27: Tractor | C27: Belorus 1221.3 | D27: TBN | E27: 329 | F27: TBN 329 | G27: 41333100 | J27: SBO | K27: Manole Serghei / Matei Timofei
A28: 68 | B28: Remorcă | C28: nou | D28: RTL | E28: 362 | F28: RTL 362 | G28: 50067200 | J28: SBO | K28: Manole Serghei / Matei Timofei
A29: 69 | B29: Tractor | C29: T-25 | D29: CC | E29: 322 | F29: CC 322 | G29: 41228800 | J29: Vadul lui Vodă | K29: Caimacan Ruslan
A30: 72 | B30: Încărcător | C30: Case 440 | D30: f/n | E30: n | F30: f/n | G30: 42676100 | H30: 2013 | J30: Energetic | K30: ???
A31: 77 | B31: Încărcător | C31: Volvo 20F | D31: TAY | E31: 66 | F31: TAY 066 | G31: 42783996 | H31: 2019 | J31: Repartizare | K31: Roșca Mihail
A32: 80 | B32: Duldozer | C32: DZ 42 | D32: TAW | E32: 114 | F32: 114 TAW | G32: 42473600 | J32: Vadul lui Vodă | K32: Caimacan Ruslan
A33: 83 | B33: Excavatoare | C33: ĂO-2621 | D33: CA | E33: 437 | F33: CA 437 | G33: 42492600 | H33: 1988 | J33: Vadul lui Vodă | K33: Cazac Iurie
A34: 84 | B34: Încărcător | C34: T 156 B | D34: CD | E34: 866 | F34: CD 866 | G34: 42628300 | H34: 2006 | J34: SBO | K34: Popa Constatin
A35: 85 | B35: Excavatoare | C35: Borax 2203 | D35: CD | E35: 946 | F35: CD 946 | G35: 42629100 | H35: 2005 | J35: Vadul lui Vodă | K35: Zatic Vleriu
A36: 103 | B36: Basculantă | C36: Kamaz 55111 | D36: CBE | E36: 276 | F36: CBE 276 | G36: 45251200 | H36: 1988 | J36: Repartizare | K36: Ionel Victor / Apavaloae Gheorghii
A37: 111 | B37: Automacara | C37: MAZ 5337 | D37: CBE | E37: 638 | F37: CBE 638 | G37: 42341400 | H37: 1988 | J37: Repartizare | K37: Alexei Constantin
A38: 112 | B38: Basculantă | C38: Kamaz 55111 | D38: CCR | E38: 871 | F38: CCR 871 | G38: 45340000 | H38: 1995 | J38: Repartizare | K38: Boicu Iurie
A39: 113 | B39: Basculantă | C39: Kamaz 65115 | D39: CHN | E39: 349 | F39: CHN 349 | G39: 50055500 | H39: 2002 | J39: Repartizare | K39: David Ion
A40: 120 | B40: Furgon | C40: IVECO DAILY | D40: SYR | E40: 744 | F40: SYR 744 | G40: 50062996 | H40: 2016 | J40: Buiucani (3) | K40: Furnica Ion
...

Sheet Acumulatoare
A1: Nr. Garaj | B1: Destinatia | C1: Marcă / Model | D1: Nr. | E1: Nr. | F1: Nr. înmatriculare | G1: model acum | H1: data instalarii | I1: data schimbat | J1: luni nominal | K1: luni ramase
A2: 77 | B2: Încărcător | C2: Volvo 20F | D2: TAY | E2: 66 | F2: TAY 066 | H2: 0 | I2: =EDATE(H2,J2) -> 731 | J2: 24 | K2: =IF(I2 < TODAY(), -DATEDIF(I2, TODAY(), "M"), DATEDIF(TODAY(), I2, "M")) -> -1492
A3: 83 | B3: Excavatoare | C3: ĂO-2621 | D3: CA | E3: 437 | F3: CA 437 | H3: 0 | I3: =EDATE(H3,J3) -> 731 | J3: 24 | K3: =IF(I3 < TODAY(), -DATEDIF(I3, TODAY(), "M"), DATEDIF(TODAY(), I3, "M")) -> -1492
A4: 69 | B4: Tractor | C4: T-25 | D4: CC | E4: 322 | F4: CC 322 | G4: 74 | H4: 43831 | I4: =EDATE(H4,J4) -> 44562 | J4: 24 | K4: =IF(I4 < TODAY(), -DATEDIF(I4, TODAY(), "M"), DATEDIF(TODAY(), I4, "M")) -> -52
A5: 156 | B5: Autoturn | C5: Gaz 5307 | D5: CBE | E5: 641 | F5: CBE 641 | G5: 75 | H5: 44532 | I5: =EDATE(H5,J5) -> 45262 | J5: 24 | K5: =IF(I5 < TODAY(), -DATEDIF(I5, TODAY(), "M"), DATEDIF(TODAY(), I5, "M")) -> -29
A6: 72 | B6: Încărcător | C6: Case 440 | D6: f/n | E6: n | F6: f/n | G6: 77 | H6: 44562 | I6: =EDATE(H6,J6) -> 45292 | J6: 24 | K6: =IF(I6 < TODAY(), -DATEDIF(I6, TODAY(), "M"), DATEDIF(TODAY(), I6, "M")) -> -28
A7: 124 | B7: Furgon | C7: IVECO DAILY | D7: SYR | E7: 759 | F7: SYR 759 | G7: 110 | H7: 44926 | I7: =EDATE(H7,J7) -> 45657 | J7: 24 | K7: =IF(I7 < TODAY(), -DATEDIF(I7, TODAY(), "M"), DATEDIF(TODAY(), I7, "M")) -> -16
A8: 111 | B8: Automacara | C8: MAZ 5337 | D8: CBE | E8: 638 | F8: CBE 638 | G8: 190 | H8: 46082 | I8: =EDATE(H8,J8) -> 46813 | J8: 24 | K8: =IF(I8 < TODAY(), -DATEDIF(I8, TODAY(), "M"), DATEDIF(TODAY(), I8, "M")) -> 21
A9: 111 | B9: Automacara | C9: MAZ 5337 | D9: CBE | E9: 638 | F9: CBE 638 | G9: 190 | H9: 46082 | I9: =EDATE(H9,J9) -> 46813 | J9: 24 | K9: =IF(I9 < TODAY(), -DATEDIF(I9, TODAY(), "M"), DATEDIF(TODAY(), I9, "M")) -> 21
A10: 53 | B10: Excavatoare | C10: ĂO-2621 | D10: CA | E10: 76 | F10: CA 076 | G10: 75 | H10: 45108 | I10: =EDATE(H10,J10) -> 45839 | J10: 24 | K10: =IF(I10 < TODAY(), -DATEDIF(I10, TODAY(), "M"), DATEDIF(TODAY(), I10, "M")) -> -10
A11: 148 | B11: Autocamion | C11: Uaz 33039 | D11: CIA | E11: 483 | F11: CIA 483 | G11: 60 | H11: 45169 | I11: =EDATE(H11,J11) -> 45900 | J11: 24 | K11: =IF(I11 < TODAY(), -DATEDIF(I11, TODAY(), "M"), DATEDIF(TODAY(), I11, "M")) -> -8
A12: 147 | B12: Basculantă | C12: Gaz SAZ 3507 | D12: CBE | E12: 267 | F12: CBE 267 | G12: 75 | H12: 45199 | I12: =EDATE(H12,J12) -> 45930 | J12: 24 | K12: =IF(I12 < TODAY(), -DATEDIF(I12, TODAY(), "M"), DATEDIF(TODAY(), I12, "M")) -> -7
A13: 69 | B13: Tractor | C13: T-25 | D13: CC | E13: 322 | F13: CC 322 | G13: 75 | H13: 45199 | I13: =EDATE(H13,J13) -> 45930 | J13: 24 | K13: =IF(I13 < TODAY(), -DATEDIF(I13, TODAY(), "M"), DATEDIF(TODAY(), I13, "M")) -> -7
A14: 22 | B14: Excavatoare | C14: JCB 8030 ZTS | D14: TAE | E14: 465 | F14: TAE 465 | G14: 75 | H14: 45199 | I14: =EDATE(H14,J14) -> 45930 | J14: 24 | K14: =IF(I14 < TODAY(), -DATEDIF(I14, TODAY(), "M"), DATEDIF(TODAY(), I14, "M")) -> -7
A15: 23 | B15: Excavatoare | C15: JCB 8030 ZTS | D15: TAE | E15: 466 | F15: TAE 466 | G15: 75 | H15: 45199 | I15: =EDATE(H15,J15) -> 45930 | J15: 24 | K15: =IF(I15 < TODAY(), -DATEDIF(I15, TODAY(), "M"), DATEDIF(TODAY(), I15, "M")) -> -7
A16: 24 | B16: Excavatoare | C16: JCB 8030 ZTS | D16: TAE | E16: 467 | F16: TAE 467 | G16: 75 | H16: 45199 | I16: =EDATE(H16,J16) -> 45930 | J16: 24 | K16: =IF(I16 < TODAY(), -DATEDIF(I16, TODAY(), "M"), DATEDIF(TODAY(), I16, "M")) -> -7
A17: 112 | B17: Basculantă | C17: Kamaz 55111 | D17: CCR | E17: 871 | F17: CCR 871 | G17: 180 | H17: 45199 | I17: =EDATE(H17,J17) -> 45930 | J17: 24 | K17: =IF(I17 < TODAY(), -DATEDIF(I17, TODAY(), "M"), DATEDIF(TODAY(), I17, "M")) -> -7
A18: 112 | B18: Basculantă | C18: Kamaz 55111 | D18: CCR | E18: 871 | F18: CCR 871 | G18: 180 | H18: 45199 | I18: =EDATE(H18,J18) -> 45930 | J18: 24 | K18: =IF(I18 < TODAY(), -DATEDIF(I18, TODAY(), "M"), DATEDIF(TODAY(), I18, "M")) -> -7
... A75: 34 | B75: Excavatoare | C75: JCB 8030 ZTS | D75: TAE | E75: 469 | F75: TAE 469 | G75: 75 | H75: 46053 | I75: =EDATE(H75,J75) -> 46783 | J75: 24 | K75: =IF(I75 < TODAY(), -DATEDIF(I75, TODAY(), "M"), DATEDIF(TODAY(), I75, "M")) -> 20

Sheet Anvelope
A1: 1 | B1: Nr. Garaj | C1: Destinatia | D1: Marcă / Model | E1: Nr. înmatriculare | F1: Nr. înmatriculare | G1: Nr. înmatriculare | H1: model anvelopa | I1: data instalarii | J1: data schimbat | K1: luni nominal | L1: luni ramase | N1: 1 | O1: Nr. Garaj | P1: Destinatia | Q1: Marcă / Model | R1: Nr. înmatriculare | S1: Nr. înmatriculare | T1: Nr. înmatriculare | U1: model anvelopa | V1: data instalarii | W1: Km la instalare | X1: norma de uzura | Y1: kilometraj prognozat schimb | Z1: Km ramas | AA1: Procent uzura | AB1: kilometraj actual schimb
A2: 2 | B2: 1 | C2: Excavatoare | D2: JCB 3CX | E2: TAE | F2: 471 | G2: TAE 471 | H2: 12,5-18 R 4 | I2: 45901 | J2: =EDATE(I2,K2) -> 46569 | K2: 22 | L2: =IF(J2 < TODAY(), -DATEDIF(J2, TODAY(), "M"), DATEDIF(TODAY(), J2, "M")) -> 13 | N2: 2 | O2: 103 | P2: Basculantă | Q2: Kamaz 55111 | R2: CBE | S2: 276 | T2: CBE 276 | U2: 9,0 R20 | V2: 45566 | W2: 39697 | X2: 47000 | Y2: =W2+X2 -> 86697 | Z2: =Y2-AB2 -> 27130 | AA2: =(AB2-W2)/X2*100 -> 42.276596 | AB2: 59567
A3: 3 | B3: 1 | C3: Excavatoare | D3: JCB 3CX | E3: TAE | F3: 471 | G3: TAE 471 | H3: 12,5-18 R 4 | I3: 45901 | J3: =EDATE(I3,K3) -> 46569 | K3: 22 | L3: =IF(J3 < TODAY(), -DATEDIF(J3, TODAY(), "M"), DATEDIF(TODAY(), J3, "M")) -> 13 | N3: 3 | O3: 103 | P3: Basculantă | Q3: Kamaz 55111 | R3: CBE | S3: 276 | T3: CBE 276 | U3: 9,0 R20 | V3: 45566 | W3: 39697 | X3: 47000 | Y3: =W3+X3 -> 86697 | Z3: =Y3-AB3 -> 27130 | AA3: =(AB3-W3)/X3*100 -> 42.276596 | AB3: =AB2 -> 59567
A4: 4 | B4: 1 | C4: Excavatoare | D4: JCB 3CX | E4: TAE | F4: 471 | G4: TAE 471 | H4: 18,4-26 TD-19 | I4: 45901 | J4: =EDATE(I4,K4) -> 46569 | K4: 22 | L4: =IF(J4 < TODAY(), -DATEDIF(J4, TODAY(), "M"), DATEDIF(TODAY(), J4, "M")) -> 13 | N4: 4 | O4: 103 | P4: Basculantă | Q4: Kamaz 55111 | R4: CBE | S4: 276 | T4: CBE 276 | U4: 9,0 R20 | V4: 45566 | W4: 39697 | X4: 47000 | Y4: =W4+X4 -> 86697 | Z4: =Y4-AB4 -> 27130 | AA4: =(AB4-W4)/X4*100 -> 42.276596 | AB4: =AB3 -> 59567
A5: 5 | B5: 1 | C5: Excavatoare | D5: JCB 3CX | E5: TAE | F5: 471 | G5: TAE 471 | H5: 18,4-26 TD-19 | I5: 45901 | J5: =EDATE(I5,K5) -> 46569 | K5: 22 | L5: =IF(J5 < TODAY(), -DATEDIF(J5, TODAY(), "M"), DATEDIF(TODAY(), J5, "M")) -> 13 | N5: 5 | O5: 103 | P5: Basculantă | Q5: Kamaz 55111 | R5: CBE | S5: 276 | T5: CBE 276 | U5: 9,0 R20 | V5: 45566 | W5: 39697 | X5: 47000 | Y5: =W5+X5 -> 86697 | Z5: =Y5-AB5 -> 27130 | AA5: =(AB5-W5)/X5*100 -> 42.276596 | AB5: =AB4 -> 59567
A6: 6 | B6: - | C6: - | D6: - | E6: - | F6: - | G6: - | H6: - | I6: - | J6: - | K6: - | L6: - | N6: 6 | O6: 103 | P6: Basculantă | Q6: Kamaz 55111 | R6: CBE | S6: 276 | T6: CBE 276 | U6: 9,0 R20 | V6: 45689 | W6: 43391 | X6: 47000 | Y6: =W6+X6 -> 90391 | Z6: =Y6-AB6 -> 30824 | AA6: =(AB6-W6)/X6*100 -> 34.417021 | AB6: =AB5 -> 59567
A7: 7 | B7: 2 | C7: Excavatoare | D7: JCB 3CX | E7: TAE | F7: 472 | G7: TAE 472 | H7: 12,5-18 R 4 | I7: 45443 | J7: =EDATE(I7,K7) -> 46112 | K7: 22 | L7: =IF(J7 < TODAY(), -DATEDIF(J7, TODAY(), "M"), DATEDIF(TODAY(), J7, "M")) -> -1 | N7: 7 | O7: 103 | P7: Basculantă | Q7: Kamaz 55111 | R7: CBE | S7: 276 | T7: CBE 276 | U7: 9,0 R20 | V7: 45689 | W7: 43391 | X7: 47000 | Y7: =W7+X7 -> 90391 | Z7: =Y7-AB7 -> 30824 | AA7: =(AB7-W7)/X7*100 -> 34.417021 | AB7: =AB6 -> 59567
A8: 8 | B8: 2 | C8: Excavatoare | D8: JCB 3CX | E8: TAE | F8: 472 | G8: TAE 472 | H8: 12,5-18 R 4 | I8: 45443 | J8: =EDATE(I8,K8) -> 46112 | K8: 22 | L8: =IF(J8 < TODAY(), -DATEDIF(J8, TODAY(), "M"), DATEDIF(TODAY(), J8, "M")) -> -1 | N8: 8 | O8: 103 | P8: Basculantă | Q8: Kamaz 55111 | R8: CBE | S8: 276 | T8: CBE 276 | U8: 9,0 R20 | V8: 46022 | W8: 59567 | X8: 25000 | Y8: =W8+X8 -> 84567 | Z8: =Y8-AB8 -> 25000 | AA8: =(AB8-W8)/X8*100 -> 0 | AB8: =AB7 -> 59567
A9: 9 | B9: 2 | C9: Excavatoare | D9: JCB 3CX | E9: TAE | F9: 472 | G9: TAE 472 | H9: 18,4-26 TD-19 | I9: 45716 | J9: =EDATE(I9,K9) -> 46384 | K9: 22 | L9: =IF(J9 < TODAY(), -DATEDIF(J9, TODAY(), "M"), DATEDIF(TODAY(), J9, "M")) -> 7 | N9: 9 | O9: 103 | P9: Basculantă | Q9: Kamaz 55111 | R9: CBE | S9: 276 | T9: CBE 276 | U9: 9,0 R20 | V9: 46022 | W9: 59567 | X9: 25000 | Y9: =W9+X9 -> 84567 | Z9: =Y9-AB9 -> 25000 | AA9: =(AB9-W9)/X9*100 -> 0 | AB9: =AB8 -> 59567
A10: 10 | B10: 2 | C10: Excavatoare | D10: JCB 3CX | E10: TAE | F10: 472 | G10: TAE 472 | H10: 18,4-26 TD-19 | I10: 45716 | J10: =EDATE(I10,K10) -> 46384 | K10: 22 | L10: =IF(J10 < TODAY(), -DATEDIF(J10, TODAY(), "M"), DATEDIF(TODAY(), J10, "M")) -> 7 | N10: 10 | O10: 103 | P10: Basculantă | Q10: Kamaz 55111 | R10: CBE | S10: 276 | T10: CBE 276 | U10: 9,0 R20 | V10: 46022 | W10: 59567 | X10: 25000 | Y10: =W10+X10 -> 84567 | Z10: =Y10-AB10 -> 25000 | AA10: =(AB10-W10)/X10*100 -> 0 | AB10: =AB9 -> 59567
A11: 11 | B11: - | C11: - | D11: - | E11: - | F11: - | G11: - | H11: - | I11: - | J11: - | K11: - | L11: - | N11: 11 | O11: 103 | P11: Basculantă | Q11: Kamaz 55111 | R11: CBE | S11: 276 | T11: CBE 276 | U11: 9,0 R20 | V11: 46022 | W11: 59567 | X11: 25000 | Y11: =W11+X11 -> 84567 | Z11: =Y11-AB11 -> 25000 | AA11: =(AB11-W11)/X11*100 -> 0 | AB11: =AB10 -> 59567
A12: 12 | B12: 3 | C12: Excavatoare | D12: JCB 3CX | E12: TAE | F12: 474 | G12: TAE 474 | H12: 12,5-18 R 4 | I12: 45412 | J12: =EDATE(I12,K12) -> 46081 | K12: 22 | L12: =IF(J12 < TODAY(), -DATEDIF(J12, TODAY(), "M"), DATEDIF(TODAY(), J12, "M")) -> -2 | N12: 12 | O12: - | P12: - | Q12: - | R12: - | S12: - | T12: - | U12: - | V12: - | W12: - | X12: - | Y12: - | Z12: - | AA12: - | AB12: -
A13: 13 | B13: 3 | C13: Excavatoare | D13: JCB 3CX | E13: TAE | F13: 474 | G13: TAE 474 | H13: 12,5-18 R 4 | I13: 45412 | J13: =EDATE(I13,K13) -> 46081 | K13: 22 | L13: =IF(J13 < TODAY(), -DATEDIF(J13, TODAY(), "M"), DATEDIF(TODAY(), J13, "M")) -> -2 | N13: 13 | O13: 111 | P13: Automacara | Q13: MAZ 5337 | R13: CBE | S13: 638 | T13: CBE 638 | U13: 12,00 R 20 | V13: 46143 | W13: 73497 | X13: 23000 | Y13: =W13+X13 -> 96497 | Z13: =Y13-AB13 -> 23000 | AA13: =(AB13-W13)/X13*100 -> 0 | AB13: 73497
A14: 14 | B14: 3 | C14: Excavatoare | D14: JCB 3CX | E14: TAE | F14: 474 | G14: TAE 474 | H14: 18,4-26 TD-19 | I14: 45260 | J14: =EDATE(I14,K14) -> 45930 | K14: 22 | L14: =IF(J14 < TODAY(), -DATEDIF(J14, TODAY(), "M"), DATEDIF(TODAY(), J14, "M")) -> -7 | N14: 14 | O14: 111 | P14: Automacara | Q14: MAZ 5337 | R14: CBE | S14: 638 | T14: CBE 638 | U14: 12,00 R 20 | V14: 46143 | W14: 73497 | X14: 23000 | Y14: =W14+X14 -> 96497 | Z14: =Y14-AB14 -> 23000 | AA14: =(AB14-W14)/X14*100 -> 0 | AB14: =AB13 -> 73497
A15: 15 | B15: 3 | C15: Excavatoare | D15: JCB 3CX | E15: TAE | F15: 474 | G15: TAE 474 | H15: 18,4-26 TD-19 | I15: 45260 | J15: =EDATE(I15,K15) -> 45930 | K15: 22 | L15: =IF(J15 < TODAY(), -DATEDIF(J15, TODAY(), "M"), DATEDIF(TODAY(), J15, "M")) -> -7 | N15: 15 | O15: 111 | P15: Automacara | Q15: MAZ 5337 | R15: CBE | S15: 638 | T15: CBE 638 | U15: 12,00 R 20 | V15: 41913 | W15: 59768 | X15: 40000 | Y15: =W15+X15 -> 99768 | Z15: =Y15-AB15 -> 26271 | AA15: =(AB15-W15)/X15*100 -> 34.3225 | AB15: =AB14 -> 73497
A16: 16 | B16: - | C16: - | D16: - | E16: - | F16: - | G16: - | H16: - | I16: - | J16: - | K16: - | L16: - | N16: 16 | O16: 111 | P16: Automacara | Q16: MAZ 5337 | R16: CBE | S16: 638 | T16: CBE 638 | U16: 12,00 R 20 | V16: 41913 | W16: 59768 | X16: 40000 | Y16: =W16+X16 -> 99768 | Z16: =Y16-AB16 -> 26271 | AA16: =(AB16-W16)/X16*100 -> 34.3225 | AB16: =AB15 -> 73497
A17: 17 | B17: 4 | C17: Excavatoare | D17: JCB 3CX | E17: TAE | F17: 473 | G17: TAE 473 | H17: 12,5-18 R 4 | I17: 45901 | J17: =EDATE(I17,K17) -> 46569 | K17: 22 | L17: =IF(J17 < TODAY(), -DATEDIF(J17, TODAY(), "M"), DATEDIF(TODAY(), J17, "M")) -> 13 | N17: 17 | O17: 111 | P17: Automacara | Q17: MAZ 5337 | R17: CBE | S17: 638 | T17: CBE 638 | U17: 12,00 R 20 | V17: 43862 | W17: 59768 | X17: 40000 | Y17: =W17+X17 -> 99768 | Z17: =Y17-AB17 -> 26271 | AA17: =(AB17-W17)/X17*100 -> 34.3225 | AB17: =AB16 -> 73497
A18: 18 | B18: 4 | C18: Excavatoare | D18: JCB 3CX | E18: TAE | F18: 473 | G18: TAE 473 | H18: 12,5-18 R 4 | I18: 45901 | J18: =EDATE(I18,K18) -> 46569 | K18: 22 | L18: =IF(J18 < TODAY(), -DATEDIF(J18, TODAY(), "M"), DATEDIF(TODAY(), J18, "M")) -> 13 | N18: 18 | O18: 111 | P18: Automacara | Q18: MAZ 5337 | R18: CBE | S18: 638 | T18: CBE 638 | U18: 12,00 R 20 | V18: 43862 | W18: 59768 | X18: 40000 | Y18: =W18+X18 -> 99768 | Z18: =Y18-AB18 -> 26271 | AA18: =(AB18-W18)/X18*100 -> 34.3225 | AB18: =AB17 -> 73497
A19: 19 | B19: 4 | C19: Excavatoare | D19: JCB 3CX | E19: TAE | F19: 473 | G19: TAE 473 | H19: 18,4-26 TD-19 | I19: 45901 | J19: =EDATE(I19,K19) -> 46569 | K19: 22 | L19: =IF(J19 < TODAY(), -DATEDIF(J19, TODAY(), "M"), DATEDIF(TODAY(), J19, "M")) -> 13 | N19: 23 | O19: - | P19: - | Q19: - | R19: - | S19: - | T19: - | U19: - | V19: - | W19: - | X19: - | Y19: - | Z19: - | AA19: - | AB19: -
A20: 20 | B20: 4 | C20: Excavatoare | D20: JCB 3CX | E20: TAE | F20: 473 | G20: TAE 473 | H20: 18,4-26 TD-19 | I20: 45901 | J20: =EDATE(I20,K20) -> 46569 | K20: 22 | L20: =IF(J20 < TODAY(), -DATEDIF(J20, TODAY(), "M"), DATEDIF(TODAY(), J20, "M")) -> 13 | N20: 24 | O20: 112 | P20: Basculantă | Q20: Kamaz 55111 | R20: CCR | S20: 871 | T20: CCR 871 | U20: 9,0 R20 | V20: 44865 | W20: 11261 | X20: 47000 | Y20: =W20+X20 -> 58261 | Z20: =Y20-AB20 -> 13116 | AA20: =(AB20-W20)/X20*100 -> 72.093617 | AB20: 45145
A21: 21 | B21: - | C21: - | D21: - | E21: - | F21: - | G21: - | H21: - | I21: - | J21: - | K21: - | L21: - | N21: 25 | O21: 112 | P21: Basculantă | Q21: Kamaz 55111 | R21: CCR | S21: 871 | T21: CCR 871 | U21: 9,0 R20 | V21: 44865 | W21: 11261 | X21: 47000 | Y21: =W21+X21 -> 58261 | Z21: =Y21-AB21 -> 13116 | AA21: =(AB21-W21)/X21*100 -> 72.093617 | AB21: =AB20 -> 45145
A22: 22 | B22: 8 | C22: Tractor | D22: Foton 545 | E22: CH | F22: 340 | G22: CH 340 | H22: 8,3-20 | I22: 46081 | J22: =EDATE(I22,K22) -> 46811 | K22: 24 | L22: =IF(J22 < TODAY(), -DATEDIF(J22, TODAY(), "M"), DATEDIF(TODAY(), J22, "M")) -> 21 | N22: 26 | O22: 112 | P22: Basculantă | Q22: Kamaz 55111 | R22: CCR | S22: 871 | T22: CCR 871 | U22: 9,0 R20 | V22: 45748 | W22: 33982 | X22: 47000 | Y22: =W22+X22 -> 80982 | Z22: =Y22-AB22 -> 35837 | AA22: =(AB22-W22)/X22*100 -> 23.751064 | AB22: =AB21 -> 45145
A23: 23 | B23: 8 | C23: Tractor | D23: Foton 545 | E23: CH | F23: 340 | G23: CH 340 | H23: 8,3-20 | I23: 46081 | J23: =EDATE(I23,K23) -> 46811 | K23: 24 | L23: =IF(J23 < TODAY(), -DATEDIF(J23, TODAY(), "M"), DATEDIF(TODAY(), J23, "M")) -> 21 | N23: 27 | O23: 112 | P23: Basculantă | Q23: Kamaz 55111 | R23: CCR | S23: 871 | T23: CCR 871 | U23: 9,0 R20 | V23: 45748 | W23: 33982 | X23: 47000 | Y23: =W23+X23 -> 80982 | Z23: =Y23-AB23 -> 35837 | AA23: =(AB23-W23)/X23*100 -> 23.751064 | AB23: =AB22 -> 45145
A24: 24 | B24: 8 | C24: Tractor | D24: Foton 545 | E24: CH | F24: 340 | G24: CH 340 | H24: 12,4-28 | I24: 46081 | J24: =EDATE(I24,K24) -> 46811 | K24: 24 | L24: =IF(J24 < TODAY(), -DATEDIF(J24, TODAY(), "M"), DATEDIF(TODAY(), J24, "M")) -> 21 | N24: 28 | O24: 112 | P24: Basculantă | Q24: Kamaz 55111 | R24: CCR | S24: 871 | T24: CCR 871 | U24: 9,0 R20 | V24: 45748 | W24: 33982 | X24: 47000 | Y24: =W24+X24 -> 80982 | Z24: =Y24-AB24 -> 35837 | AA24: =(AB24-W24)/X24*100 -> 23.751064 | AB24: =AB23 -> 45145
A25: 25 | B25: 8 | C25: Tractor | D25: Foton 545 | E25: CH | F25: 340 | G25: CH 340 | H25: 12,4-28 | I25: 46081 | J25: =EDATE(I25,K25) -> 46811 | K25: 24 | L25: =IF(J25 < TODAY(), -DATEDIF(J25, TODAY(), "M"), DATEDIF(TODAY(), J25, "M")) -> 21 | N25: 29 | O25: 112 | P25: Basculantă | Q25: Kamaz 55111 | R25: CCR | S25: 871 | T25: CCR 871 | U25: 9,0 R20 | V25: 45748 | W25: 33982 | X25: 47000 | Y25: =W25+X25 -> 80982 | Z25: =Y25-AB25 -> 35837 | AA25: =(AB25-W25)/X25*100 -> 23.751064 | AB25: =AB24 -> 45145
A26: 26 | B26: - | C26: - | D26: - | E26: - | F26: - | G26: - | H26: - | I26: - | J26: - | K26: - | L26: - | N26: 30 | O26: 112 | P26: Basculantă | Q26: Kamaz 55111 | R26: CCR | S26: 871 | T26: CCR 871 | U26: 9,0 R20 | V26: 45870 | W26: 37001 | X26: 47000 | Y26: =W26+X26 -> 84001 | Z26: =Y26-AB26 -> 38856 | AA26: =(AB26-W26)/X26*100 -> 17.32766 | AB26: =AB25 -> 45145
A27: 27 | B27: 9 | C27: Excavatoare | D27: JCB 3CX | E27: TAE | F27: 470 | G27: TAE 470 | H27: 12,5-18 R 4 | I27: 45689 | J27: =EDATE(I27,K27) -> 46357 | K27: 22 | L27: =IF(J27 < TODAY(), -DATEDIF(J27, TODAY(), "M"), DATEDIF(TODAY(), J27, "M")) -> 6 | N27: 31 | O27: 112 | P27: Basculantă | Q27: Kamaz 55111 | R27: CCR | S27: 871 | T27: CCR 871 | U27: 9,0 R20 | V27: 45870 | W27: 37001 | X27: 47000 | Y27: =W27+X27 -> 84001 | Z27: =Y27-AB27 -> 38856 | AA27: =(AB27-W27)/X27*100 -> 17.32766 | AB27: =AB26 -> 45145
A28: 28 | B28: 9 | C28: Excavatoare | D28: JCB 3CX | E28: TAE | F28: 470 | G28: TAE 470 | H28: 12,5-18 R 4 | I28: 45689 | J28: =EDATE(I28,K28) -> 46357 | K28: 22 | L28: =IF(J28 < TODAY(), -DATEDIF(J28, TODAY(), "M"), DATEDIF(TODAY(), J28, "M")) -> 6 | N28: 32 | O28: 112 | P28: Basculantă | Q28: Kamaz 55111 | R28: CCR | S28: 871 | T28: CCR 871 | U28: 9,0 R20 | V28: 45870 | W28: 37001 | X28: 47000 | Y28: =W28+X28 -> 84001 | Z28: =Y28-AB28 -> 38856 | AA28: =(AB28-W28)/X28*100 -> 17.32766 | AB28: =AB27 -> 45145
A29: 29 | B29: 9 | C29: Excavatoare | D29: JCB 3CX | E29: TAE | F29: 470 | G29: TAE 470 | H29: 18,4-26 | I29: 46081 | J29: =EDATE(I29,K29) -> 46811 | K29: 24 | L29: =IF(J29 < TODAY(), -DATEDIF(J29, TODAY(), "M"), DATEDIF(TODAY(), J29, "M")) -> 21 | N29: 33 | O29: 112 | P29: Basculantă | Q29: Kamaz 55111 | R29: CCR | S29: 871 | T29: CCR 871 | U29: 9,0 R20 | V29: 45870 | W29: 37001 | X29: 47000 | Y29: =W29+X29 -> 84001 | Z29: =Y29-AB29 -> 38856 | AA29: =(AB29-W29)/X29*100 -> 17.32766 | AB29: =AB28 -> 45145
A30: 30 | B30: 9 | C30: Excavatoare | D30: JCB 3CX | E30: TAE | F30: 470 | G30: TAE 470 | H30: 18,4-26 | I30: 46081 | J30: =EDATE(I30,K30) -> 46811 | K30: 24 | L30: =IF(J30 < TODAY(), -DATEDIF(J30, TODAY(), "M"), DATEDIF(TODAY(), J30, "M")) -> 21 | N30: 34 | O30: - | P30: - | Q30: - | R30: - | S30: - | T30: - | U30: - | V30: - | W30: - | X30: - | Y30: - | Z30: - | AA30: - | AB30: -
A31: 31 | B31: - | C31: - | D31: - | E31: - | F31: - | G31: - | H31: - | I31: - | J31: - | K31: - | L31: - | N31: 35 | O31: 113 | P31: Basculantă | Q31: Kamaz 65115 | R31: CHN | S31: 349 | T31: CHN 349 | U31: 10,0 R 20 | V31: 45931 | W31: 92832 | X31: 47000 | Y31: =W31+X31 -> 139832 | Z31: =Y31-AB31 -> 44394 | AA31: =(AB31-W31)/X31*100 -> 5.5446809 | AB31: 95438
A32: 32 | B32: 10 | C32: Excavatoare | D32: JCB 3CX | E32: TAE | F32: 586 | G32: TAE 586 | H32: 12,5-18 R 4 | I32: 45016 | J32: =EDATE(I32,K32) -> 45688 | K32: 22 | L32: =IF(J32 < TODAY(), -DATEDIF(J32, TODAY(), "M"), DATEDIF(TODAY(), J32, "M")) -> -15 | N32: 36 | O32: 113 | P32: Basculantă | Q32: Kamaz 65115 | R32: CHN | S32: 349 | T32: CHN 349 | U32: 10,0 R 20 | V32: 45931 | W32: 92832 | X32: 47000 | Y32: =W32+X32 -> 139832 | Z32: =Y32-AB32 -> 44394 | AA32: =(AB32-W32)/X32*100 -> 5.5446809 | AB32: =AB31 -> 95438
A33: 33 | B33: 10 | C33: Excavatoare | D33: JCB 3CX | E33: TAE | F33: 586 | G33: TAE 586 | H33: 12,5-18 R 4 | I33: 45016 | J33: =EDATE(I33,K33) -> 45688 | K33: 22 | L33: =IF(J33 < TODAY(), -DATEDIF(J33, TODAY(), "M"), DATEDIF(TODAY(), J33, "M")) -> -15 | N33: 37 | O33: 113 | P33: Basculantă | Q33: Kamaz 65115 | R33: CHN | S33: 349 | T33: CHN 349 | U33: 10,0 R 20 | V33: 45991 | W33: 93676 | X33: 25000 | Y33: =W33+X33 -> 118676 | Z33: =Y33-AB33 -> 23238 | AA33: =(AB33-W33)/X33*100 -> 7.048 | AB33: =AB32 -> 95438
A34: 34 | B34: 10 | C34: Excavatoare | D34: JCB 3CX | E34: TAE | F34: 586 | G34: TAE 586 | H34: 18,4-26 TD-19 | I34: 45443 | J34: =EDATE(I34,K34) -> 46112 | K34: 22 | L34: =IF(J34 < TODAY(), -DATEDIF(J34, TODAY(), "M"), DATEDIF(TODAY(), J34, "M")) -> -1 | N34: 38 | O34: 113 | P34: Basculantă | Q34: Kamaz 65115 | R34: CHN | S34: 349 | T34: CHN 349 | U34: 10,0 R 20 | V34: 45991 | W34: 93676 | X34: 25000 | Y34: =W34+X34 -> 118676 | Z34: =Y34-AB34 -> 23238 | AA34: =(AB34-W34)/X34*100 -> 7.048 | AB34: =AB33 -> 95438
A35: 35 | B35: 10 | C35: Excavatoare | D35: JCB 3CX | E35: TAE | F35: 586 | G35: TAE 586 | H35: 18,4-26 TD-19 | I35: 45443 | J35: =EDATE(I35,K35) -> 46112 | K35: 22 | L35: =IF(J35 < TODAY(), -DATEDIF(J35, TODAY(), "M"), DATEDIF(TODAY(), J35, "M")) -> -1 | N35: 39 | O35: 113 | P35: Basculantă | Q35: Kamaz 65115 | R35: CHN | S35: 349 | T35: CHN 349 | U35: 10,0 R 20 | V35: 45991 | W35: 93676 | X35: 25000 | Y35: =W35+X35 -> 118676 | Z35: =Y35-AB35 -> 23238 | AA35: =(AB35-W35)/X35*100 -> 7.048 | AB35: =AB34 -> 95438
A36: 36 | B36: - | C36: - | D36: - | E36: - | F36: - | G36: - | H36: - | I36: - | J36: - | K36: - | L36: - | N36: 40 | O36: 113 | P36: Basculantă | Q36: Kamaz 65115 | R36: CHN | S36: 349 | T36: CHN 349 | U36: 10,0 R 20 | V36: 45991 | W36: 93676 | X36: 25000 | Y36: =W36+X36 -> 118676 | Z36: =Y36-AB36 -> 23238 | AA36: =(AB36-W36)/X36*100 -> 7.048 | AB36: =AB35 -> 95438
A37: 37 | B37: 11 | C37: Excavatoare | D37: JCB 3CX | E37: TAE | F37: 587 | G37: TAE 587 | H37: 12,5-18 R 4 | I37: 46053 | J37: =EDATE(I37,K37) -> 46783 | K37: 24 | L37: =IF(J37 < TODAY(), -DATEDIF(J37, TODAY(), "M"), DATEDIF(TODAY(), J37, "M")) -> 20 | N37: 41 | O37: 113 | P37: Basculantă | Q37: Kamaz 65115 | R37: CHN | S37: 349 | T37: CHN 349 | U37: 10,0 R 20 | V37: 45991 | W37: 93676 | X37: 25000 | Y37: =W37+X37 -> 118676 | Z37: =Y37-AB37 -> 23238 | AA37: =(AB37-W37)/X37*100 -> 7.048 | AB37: =AB36 -> 95438
A38: 38 | B38: 11 | C38: Excavatoare | D38: JCB 3CX | E38: TAE | F38: 587 | G38: TAE 587 | H38: 12,5-18 R 4 | I38: 46053 | J38: =EDATE(I38,K38) -> 46783 | K38: 24 | L38: =IF(J38 < TODAY(), -DATEDIF(J38, TODAY(), "M"), DATEDIF(TODAY(), J38, "M")) -> 20 | N38: 42 | O38: 113 | P38: Basculantă | Q38: Kamaz 65115 | R38: CHN | S38: 349 | T38: CHN 349 | U38: 10,0 R 20 | V38: 45991 | W38: 93676 | X38: 25000 | Y38: =W38+X38 -> 118676 | Z38: =Y38-AB38 -> 23238 | AA38: =(AB38-W38)/X38*100 -> 7.048 | AB38: =AB37 -> 95438
A39: 39 | B39: 11 | C39: Excavatoare | D39: JCB 3CX | E39: TAE | F39: 587 | G39: TAE 587 | H39: 18,4-26 TD-19 | I39: 45443 | J39: =EDATE(I39,K39) -> 46112 | K39: 22 | L39: =IF(J39 < TODAY(), -DATEDIF(J39, TODAY(), "M"), DATEDIF(TODAY(), J39, "M")) -> -1 | N39: 43 | O39: 113 | P39: Basculantă | Q39: Kamaz 65115 | R39: CHN | S39: 349 | T39: CHN 349 | U39: 10,0 R 20 | V39: 45991 | W39: 93676 | X39: 25000 | Y39: =W39+X39 -> 118676 | Z39: =Y39-AB39 -> 23238 | AA39: =(AB39-W39)/X39*100 -> 7.048 | AB39: =AB38 -> 95438
A40: 40 | B40: 11 | C40: Excavatoare | D40: JCB 3CX | E40: TAE | F40: 587 | G40: TAE 587 | H40: 18,4-26 TD-19 | I40: 45443 | J40: =EDATE(I40,K40) -> 46112 | K40: 22 | L40: =IF(J40 < TODAY(), -DATEDIF(J40, TODAY(), "M"), DATEDIF(TODAY(), J40, "M")) -> -1 | N40: 44 | O40: 113 | P40: Basculantă | Q40: Kamaz 65115 | R40: CHN | S40: 349 | T40: CHN 349 | U40: 10,0 R 20 | V40: 45991 | W40: 93676 | X40: 25000 | Y40: =W40+X40 -> 118676 | Z40: =Y40-AB40 -> 23238 | AA40: =(AB40-W40)/X40*100 -> 7.048 | AB40: =AB39 -> 95438
...

Sheet Revizii și intervenții
A1: Nr.crt | B1: Vehicul (Nr. înmatriculare) | C1: Data intervenției | D1: Tip intervenție | E1: Detalii operație | F1: Km la intervenție | G1: Cost piese (lei) | H1: Cost manoperă (lei) | I1: Total cost | J1: Atelier / Mecanic | K1: Observații
A2: 1 | B2: CMC-001 | C2: 45717 | D2: Schimb ulei | E2: Filtru ulei + ulei 5W40 | F2: 170000 | G2: 850 | H2: 250 | I2: =G2+H2 -> 1100 | J2: Sector auto intern
A3: 2
A4: 3
A5: 4
A6: 5
A7: 6
A8: 7
A9: 8
A10: 9
A11: 10
A12: 11
A13: 12
A14: 13
... A201: 200

Sheet Pașaport tehnic
A1: PAȘAPORT TEHNIC - selectați nr. înmatriculare în celula B2 pentru a afișa datele
A2: Nr. înmatriculare:
A4: Marcă/Model
A5: An fabricație
A6: VIN
A7: Nr. motor
A8: Sector
A9: Șofer curent
A10: Utilaje auxiliare
A11: Km actuali
A12: Stare tehnică
A14: Istoric deservire (filtrat din foaia 'Revizii și intervenții')
A15: Data | B15: Tip lucrare | C15: Detalii | D15: Km | E15: Cost total | F15: Mecanic

Sheet Rapoarte
A1: Indicator | B1: Valoare / Observații
A2: Număr total vehicule | B2: =COUNTA(Vehicule!F:F)-1 -> 64
A3: Număr total șoferi | B3: =COUNTA(Șoferi!A:A)-1 -> 79
A4: Total costuri revizii (an curent) | B4: =SUMIFS('Revizii și intervenții'!I:I,'Revizii și intervenții'!C:C,">=" & DATE(2025,1,1)) -> 1100

Sheet VBA_Code
A1: INSTRUCȚIUNI MACRO
A2: Macro-ul pentru generarea Pașaportului tehnic în PDF este inclus aici ca text. Pentru a folosi macro-ul: 1) Deschide Excel, apasă ALT+F11 pentru a deschide editorul VBA. 2) Insert -> Module și lipește codul din coloana A într-un modul nou. 3) Salvează fișierul ca .xlsm (Excel Macro-Enabled Workbook). 4) Revină în Excel și execută macro-ul.
A5: Sub GenereazaPasaportPDF() Dim nr As String nr = ThisWorkbook.Sheets("Pașaport tehnic").Range("B2").Value If nr = "" Then MsgBox "Introduceți numărul de înmatriculare în Pașaport tehnic!B2", vbExclamation Exit Sub End If Dim shVeh As Worksheet: Set shVeh = ThisWorkbook.Sheets("Vehicule") Dim shPas As Worksheet: Set shPas = ThisWorkbook.Sheets("Pașaport tehnic") Dim found As Range Set found = shVeh.Range("B:B").Find(What:=nr, LookAt:=xlWhole) If Not found Is Nothing Then shPas.Range("B4").Value = shVeh.Cells(found.Row, 3).Value shPas.Range("B5").Value = shVeh.Cells(found.Row, 4).Value shPas.Range("B6").Value = shVeh.Cells(found.Row, 5).Value shPas.Range("B7").Value = shVeh.Cells(found.Row, 6).Value shPas.Range("B8").Value = shVeh.Cells(found.Row, 13).Value shPas.Range("B9").Value = shVeh.Cells(found.Row, 14).Value shPas.Range("B10").Value = shVeh.Cells(found.Row, 15).Value shPas.Range("B11").Value = shVeh.Cells(found.Row, 7).Value shPas.Range("B12").Value = shVeh.Cells(found.Row, 17).Value Else MsgBox "Vehiculul nu a fost găsit în tabelul Vehicule.", vbExclamation Exit Sub End If Dim pdfPath As String pdfPath = ThisWorkbook.Path & "\" & "Pasaport_" & nr & ".pdf" shPas.ExportAsFixedFormat Type:=xlTypePDF, Filename:=pdfPath, Quality:=xlQualityStandard MsgBox "Pașaport generat: " & pdfPath, vbInformation End Sub
